date: time: 13/02/2021 12:47:28, exception type: TypeError, full traceback: ['  File "/home/blite0/Рабочий стол/git/hw/OOP/hw_4/app.py", line 26, in <module>\n    models.candidate_phyton()\n']
date: time: 13/02/2021 12:48:13, exception type: TypeError, full traceback: ['  File "/home/blite0/Рабочий стол/git/hw/OOP/hw_4/app.py", line 26, in <module>\n    models.candidate_phyton()\n']
